<?xml version="1.0"?>

<robot name="my_turtlebot" xmlns:xacro="http://ros.org/wiki/xacro">

<property name="base_x" value="0.33" />
<property name="base_y" value="0.33" />

<xacro:macro name="create">

    <link name="base_link">
        <inertial>
            <mass value="2" />
            <origin xyz="0 0 0.0" />
            <inertia ixx="0.01" ixy="0.0" ixz="0.0"
                     iyy="0.01" iyz="0.0" izz="0.5" />
        </inertial>

        <visual>
            <origin xyz=" 0 0 0.0308" rpy="0 0 0" />
            <geometry>
                <cylinder length="0.0611632" radius="0.016495"/>
            </geometry>
        </visual>

        <collision>
            <origin xyz="0.0 0.0 0.0308" rpy="0 0 0" />
            <geometry>
                <cylinder length="0.0611632" radius="0.016495"/>
            </geometry>
        </collision>
    </link>

    <link name="front_sensor_link">
        <inertial>
            <mass value="0.01" />
            <origin xyz="0 0 0"/>
            <inertia ixx="0.001" ixy="0.0" ixz="0.0" iyy="0.001" iyz="0.0" izz="0.001" />
        </inertial>
    </link>


    <joint name="base_front_sensor_joint" type="fixed">
        <origin xyz="0.09 -0.120 0.042" rpy="0 0 -1.0" />        
        <parent link="base_link"/>
        <child link="front_sensor_link" />
    </joint>

    <link name="left_wheel_link">
        <inertial>
            <origin xyz="0 0 0"/>
            <mass value="0.01" />
            <inertia ixx="0.001" ixy="0.0" ixz="0.0" iyy="0.001" iyz="0.0" izz="0.001" />
        </inertial>

        <visual>
            <origin xyz="0 0 0" rpy="0 1.5707 1.5707" />
            <geometry>
                <cylinder radius="0.033" length = "0.023"/>
            </geometry>
        </visual>

        <collision>
            <origin xyz="0 0 0" rpy="0 1.5707 1.5707" />
            <geometry>
                <cylinder radius="0.033" length = "0.023"/>
            </geometry>
        </collision>
    </link>

    <joint name="left_wheel_joint" type="continuous">
        <origin xyz="0 0.13 0.015" rpy="0 0 0"/>
        <parent link="base_link"/>
        <child link="left_wheel_link"/>
        <axis xyz="0 1 0"/>
    </joint>

    <link name="right_wheel_link">
        <inertial>
            <origin xyz="0 0 0"/>
            <mass value="0.01" />
            <inertia ixx="0.001" ixy="0.0" ixz="0.0" iyy="0.001" iyz="0.0" izz="0.001" />
        </inertial>

        <visual>
            <origin xyz="0 0 0" rpy="0 1.5707 1.5707" />
            <geometry>
                <cylinder radius="0.033" length = "0.023"/>
            </geometry>
        </visual>

        <collision>
            <origin xyz="0 0 0" rpy="0 1.5707 1.5707" />
            <geometry>
                <cylinder radius="0.033" length = "0.023"/>
            </geometry>
        </collision>
    </link>

    <joint name="right_wheel_joint" type="continuous">
        <origin xyz="0 -0.13 0.015" rpy="0 0 0"/>
        <parent link="base_link"/>
        <child link="right_wheel_link"/>
        <axis xyz="0 1 0"/>
    </joint>

    <link name="rear_wheel_link">
        <inertial>
            <origin xyz="0 0 0"/>
            <mass value="0.001" />
            <inertia ixx="0.0001" ixy="0.0" ixz="0.0" iyy="0.0001" iyz="0.0" izz="0.0001" />
        </inertial>

        <visual>
            <origin xyz="0 0 0" rpy="0 1.5707 1.5707"/>
            <geometry>
                <sphere radius="0.015" />
            </geometry>
        </visual>

        <collision>
            <origin xyz="0 0 0" rpy="0 1.5707 1.5707" />
            <geometry>
                <sphere radius="0.015" />
            </geometry>
        </collision>
    </link>

    <!-- fixed because there's no transmission -->
    <joint name="rear_castor_joint" type="fixed">
        <origin xyz="-0.13 0 0.0" rpy="0 0 0"/>
        <parent link="base_link"/>
        <child link="rear_wheel_link"/>
        <axis xyz="0 1 0"/>
    </joint>

    <joint name="gyro_joint" type="fixed">
        <axis xyz="0 1 0" />
        <origin xyz="0 0 0.04" rpy="0 0 0" />
        <parent link="base_link"/>
        <child link="gyro_link"/>
    </joint>

    <link name="gyro_link">
        <inertial>
            <mass value="0.001" />
            <origin xyz="0 0 0" rpy="0 0 0" />
            <inertia ixx="0.0001" ixy="0" ixz="0" iyy="0.000001" iyz="0" izz="0.0001" />
        </inertial>
    </link>

    <!-- Simulation sensors -->
    <gazebo>
        <!-- https://github.com/turtlebot/turtlebot_create_desktop -->
        <!-- TODO adapt the controller -->
        <plugin name="create_controller" filename="libgazebo_ros_create.so">
            <alwaysOn>true</alwaysOn>
            <node_namespace>turtlebot_node</node_namespace>
            <left_wheel_joint>left_wheel_joint</left_wheel_joint>
            <right_wheel_joint>right_wheel_joint</right_wheel_joint>
            <rear_castor_joint>rear_castor_joint</rear_castor_joint>
            <wheel_separation>.260</wheel_separation>
            <wheel_diameter>0.066</wheel_diameter>
            <base_geom>collision_base_link</base_geom>
            <updateRate>40</updateRate>
            <torque>1.0</torque>
        </plugin>
    </gazebo>

    <gazebo reference="left_wheel_link">
        <mu1 value="10"/>
        <mu2 value="10"/>
        <kp value="100000000.0"/>
        <kd value="10000.0"/>
        <fdir1 value="1 0 0"/>
    </gazebo>

    <gazebo reference="right_wheel_link">
        <mu1 value="10"/>
        <mu2 value="10"/>
        <kp value="100000000.0"/>
        <kd value="10000.0"/>
        <fdir1 value="1 0 0"/>
    </gazebo>

    <gazebo reference="rear_wheel_link">
        <mu1 value="0"/>
        <mu2 value="0"/>
        <kp value="100000000.0"/>
        <kd value="10000.0"/>
    </gazebo>

    <gazebo reference="front_sensor_link">
        <sensor type="ray" name="front_sensor">
            <always_on>true</always_on>
            <update_rate>20.0</update_rate>
            <pose>0 0 0 0 0 0</pose>
            <visualize>false</visualize>
            <ray>
                <scan>
                    <horizontal>
                        <samples>1</samples>
                        <resolution>1</resolution>
                        <min_angle>0</min_angle>
                        <max_angle>0</max_angle>
                    </horizontal>
                </scan>
                <range>
                    <min>0.01</min>
                    <max>4.00</max>
                    <resolution>0.1</resolution>
                </range>
            </ray>
        </sensor>
    </gazebo>

    <!-- http://wiki.ros.org/microstrain_3dmgx2_imu -->
    <gazebo>
        <plugin name="imu_controller" filename="libgazebo_ros_imu.so">
            <alwaysOn>true</alwaysOn>
            <updateRate>30</updateRate>
            <bodyName>gyro_link</bodyName>
            <topicName>imu/data</topicName>
            <serviceName>imu/is_calibrated</serviceName>
            <gaussianNoise>${0.0017*0.0017}</gaussianNoise>
            <xyzOffsets>0 0 0</xyzOffsets> 
            <rpyOffsets>0 0 0</rpyOffsets>
        </plugin>
    </gazebo>

</xacro:macro>

</robot>
